Workbook
Name agricode: #REF!
Name agriVar: #REF!
Name ajiC: #REF!
Name ajiR: #REF!
Name ajiS: #REF!
Name algodonC: #REF!
Name algodonP: #REF!
Name algodonPr: #REF!
Name algodonR: #REF!
Name algodonS: #REF!
Name amilaceo: #REF!
Name amilaceoC: #REF!
Name amilaceoP: #REF!
Name amilaceoPr: #REF!
Name amilaceoR: #REF!
Name amilaceoS: #REF!
Name apioC: #REF!
Name apioR: #REF!
Name apioS: #REF!
Name arrozC: #REF!
Name arrozP: #REF!
Name arrozPr: #REF!
Name arrozR: #REF!
Name arrozS: #REF!
Name arvejagsC: #REF!
Name arvejagsP: #REF!
Name arvejagsPr: #REF!
Name arvejagsR: #REF!
Name arvejagsS: #REF!
Name betarragaC: #REF!
Name betarragaR: #REF!
Name betarragaS: #REF!
Name cafeC: #REF!
Name cafeP: #REF!
Name cafePr: #REF!
Name cafeR: #REF!
Name cafeS: #REF!
Name caiguaC: #REF!
Name caiguaR: #REF!
Name caiguaS: #REF!
Name camoteC: #REF!
Name camoteP: #REF!
Name camotePr: #REF!
Name camoteR: #REF!
Name camoteS: #REF!
Name cañaC: #REF!
Name cañaP: #REF!
Name cañaPr: #REF!
Name cañaR: #REF!
Name cañaS: #REF!
Name cañihuaC: #REF!
Name cañihuaP: #REF!
Name cañihuaPr: #REF!
Name cañihuaR: #REF!
Name cañihuaS: #REF!
Name cebadac: #REF!
Name cebadaP: #REF!
Name cebadaPr: #REF!
Name cebadaR: #REF!
Name cebadas: #REF!

Sheet indicad
A1: INDICADORES ECONOMICOS
A8: Cuadro | B8: Descripción
A9: C.1 | B9: Perú: Valor de la Producción Agropecuaria, por subsectores. Enero - Junio 2020/2021 (Millones de soles a precios 2007)
A10: C.2 | B10: Perú: Evaluación de la Producción Agroindustrial de principales actividades, según producto terminado, Enero - Junio 2020/2021 (Millones de soles a precios 2007)
A11: C.3 | B11: Perú: Valor Bruto de la Producción Agropecuaria, por región, Enero - Junio 2020/2021 (Millones de soles a precios 2007 )
A12: C.4 | B12: Perú: Valor de la Producción Agropecuaria, por subsectores y principales productos, Enero - Junio 2020_2021 (Millones de soles a precios 2007)
A13: C.5 | B13: Perú: Producción Agropecuaria, por subsectores y principales productos, Enero - Junio 2020/2021 (Miles de toneladas)
A14: C.6 | B14: Perú: Valor de la Producción agropecuaria (VBP), por subsectores y principales productos, Enero - Junio 2000/2020 (Millones de soles a precio 2007)
A15: C.7 | B15: Perú: Producción agropecuaria, por subsectores y principales productos, Enero - Junio 2000/2021 (Miles de toneladas)
A16: C.8 | B16: Perú: Variación porcentual del Valor de la Producción Agropecuaria, por subsectores y principales productos, Enero -Junio 2000-2021
A17: C.9 | B17: Perú: Evaluación de la producción Agroindustrial de las principales actividades, por producto terminado (Millones de soles a precios 2007)

Sheet c-1
A1: C.1 PERÚ: VALOR BRUTO DE LA PRODUCCIÓN AGROPECUARIA POR SUBSECTORES, ENERO-JUNIO 2020-2021
A2: (Millones de soles a precios 2007)
A4: Principales productos | C4: Enero - Junio | F4: Junio
C5: 2020 p/ | D5: 2021 p/ | E5: Var. % | F5: 2020 p/ | G5: 2021 p/ | H5: Var. %
A6: Sector Agropecuario | C6: 20687.928 | D6: 20670.474 | E6: -0.084367132 | F6: 3932.3019 | G6: 4278.7816 | H6: 8.8111147
A7: Sub Sector Agrícola | C7: 13474.549 | D7: 13421.42 | E7: -0.39429143 | F7: 2719.6967 | G7: 3039.1589 | H7: 11.746244
B8: Cereales | C8: 2812.0184 | D8: 2674.2367 | E8: -4.899747 | F8: 805.93249 | G8: 1018.5024 | H8: 26.37565
B9: Hortalizas | C9: 1375.6435 | D9: 1385.1535 | E9: 0.69131302 | F9: 187.4126 | G9: 197.11694 | H9: 5.1780605
B10: Frutas y nueces | C10: 2677.6692 | D10: 2865.3362 | E10: 7.0085966 | F10: 417.31753 | G10: 456.42902 | H10: 9.372119
B11: Semillas aceiteras y frutos oleaginosos | C11: 487.49048 | D11: 459.45045 | E11: -5.7519136 | F11: 65.62971 | G11: 96.282373 | H11: 46.705466
B12: Raíces y tubérculos comestibles con alto contenido en almidón o inulina | C12: 2281.5439 | D12: 2299.0988 | E12: 0.76943184 | F12: 367.61722 | G12: 388.96635 | H12: 5.8074356
B13: Cultivos estimulantes, de especias y aromáticos | C13: 1885.3723 | D13: 1785.6286 | E13: -5.290397 | F13: 555.66628 | G13: 553.17718 | H13: -0.44794865
B14: Legumbres (hortalizas leguminosas secas) | C14: 197.74715 | D14: 206.40313 | E14: 4.3772992 | F14: 92.415616 | G14: 102.80444 | H14: 11.241415
B15: Cultivos de azúcar | C15: 352.81897 | D15: 325.17932 | E15: -7.8339453 | F15: 69.564661 | G15: 64.83658 | H15: -6.7966715
B16: Productos de forraje, fibras, plantas vivas, flores y capullos de flores, tabaco en rama y caucho natural | C16: 1403.434 | D16: 1420.1591 | E16: 1.1917284 | F16: 157.77356 | G16: 160.7352 | H16: 1.8771472
B17: Productos silvícolas y forestales | C17: 0.81116986 | D17: 0.77425801 | E17: -4.5504467 | F17: 0.36702545 | G17: 0.3083798 | H17: -15.978633
A18: Sub Sector Pecuario | C18: 7213.3788 | D18: 7249.054 | E18: 0.49456964 | F18: 1212.6052 | G18: 1239.6227 | H18: 2.2280485
B19: Animales vivos | C19: 5474.5063 | D19: 5480.6809 | E19: 0.11278679 | F19: 931.09522 | G19: 953.11069 | H19: 2.3644702
B20: Leche cruda | C20: 917.72964 | D20: 935.74722 | E20: 1.9632773 | F20: 152.51374 | G20: 156.33357 | H20: 2.5045795
B21: Huevos de gallina u otras aves, con cáscara, frescos | C21: 761.88233 | D21: 771.56467 | E21: 1.2708457 | F21: 127.08594 | G21: 128.35224 | H21: 0.99641083
B22: Otros productos de animales | C22: 59.260493 | D22: 61.061228 | E22: 3.0386775 | F22: 1.9103354 | G22: 1.8261733 | H22: -4.4056182
A23: 1/ Preliminar
A24: Elaboración: MIDAGRI-DGESEP (DEIA)

Sheet C-2
A1: C.2 PERÚ: EVALUACIÓN DE LA PRODUCCIÓN AGROINDUSTRIAL DE PRINCIPALES ACTIVIDADES,
A2: SEGÚN PRODUCTO TERMINADO
A3: (Millones de soles a precios 2007)
A5: Sector/Producto | B5: Enero - Junio | D5: Var. | E5: Junio | G5: Var.
B6: 2020p/ | C6: 2021p/ | D6: % | E6: 2020p/ | F6: 2021p/ | G6: %
A7: Sector Agroindustrial | B7: =+'[1]C-9'!B7 -> 6564.7235 | C7: =+'[1]C-9'!C7 -> 6931.0563 | D7: =+'[1]C-9'!D7 -> 5.5803236 | E7: =+'[1]C-9'!E7 -> 1182.411 | F7: =+'[1]C-9'!F7 -> 1212.0669 | G7: =+'[1]C-9'!G7 -> 2.5080858
A8: Aceites y Grasas | B8: =+'[1]C-9'!B8 -> 1079.484 | C8: =+'[1]C-9'!C8 -> 1219.5153 | D8: =+'[1]C-9'!D8 -> 12.972063 | E8: =+'[1]C-9'!E8 -> 200.97476 | F8: =+'[1]C-9'!F8 -> 224.92687 | G8: =+'[1]C-9'!G8 -> 11.91797
A9: Alimentos Balanceados | B9: =+'[1]C-9'!B15 -> 1867.9602 | C9: =+'[1]C-9'!C15 -> 1856.2588 | D9: =+'[1]C-9'!D15 -> -0.62643104 | E9: =+'[1]C-9'!E15 -> 287.98274 | F9: =+'[1]C-9'!F15 -> 320.07219 | G9: =+'[1]C-9'!G15 -> 11.142839
A10: Avena Elaborada | B10: =+'[1]C-9'!B23 -> 69.923095 | C10: =+'[1]C-9'!C23 -> 50.457618 | D10: =+'[1]C-9'!D23 -> -27.838408 | E10: =+'[1]C-9'!E23 -> 12.949288 | F10: =+'[1]C-9'!F23 -> 6.5973438 | G10: =+'[1]C-9'!G23 -> -49.052459
A11: Azúcar | B11: =+'[1]C-9'!B26 -> 657.68753 | C11: =+'[1]C-9'!C26 -> 599.39885 | D11: =+'[1]C-9'!D26 -> -8.8626709 | E11: =+'[1]C-9'!E26 -> 131.11621 | F11: =+'[1]C-9'!F26 -> 101.88416 | G11: =+'[1]C-9'!G26 -> -22.294761
A12: Embutidos y Carnes Preparadas | B12: =+'[1]C-9'!B28 -> 183.82836 | C12: =+'[1]C-9'!C28 -> 187.07356 | D12: =+'[1]C-9'!D28 -> 1.7653422 | E12: =+'[1]C-9'!E28 -> 31.853022 | F12: =+'[1]C-9'!F28 -> 33.061921 | G12: =+'[1]C-9'!G28 -> 3.7952414
A13: Espárragos | B13: =+'[1]C-9'!B38 -> 105.3253 | C13: =+'[1]C-9'!C38 -> 179.4515 | D13: =+'[1]C-9'!D38 -> 70.378347 | E13: =+'[1]C-9'!E38 -> 15.372464 | F13: =+'[1]C-9'!F38 -> 37.690189 | G13: =+'[1]C-9'!G38 -> 145.17987
A14: Fideos | B14: =+'[1]C-9'!B42 -> 483.90387 | C14: =+'[1]C-9'!C42 -> 435.26446 | D14: =+'[1]C-9'!D42 -> -10.051463 | E14: =+'[1]C-9'!E42 -> 95.097435 | F14: =+'[1]C-9'!F42 -> 76.233021 | G14: =+'[1]C-9'!G42 -> -19.836933
A15: Harina y Derivados | B15: =+'[1]C-9'!B46 -> 1117.9564 | C15: =+'[1]C-9'!C46 -> 1256.944 | D15: =+'[1]C-9'!D46 -> 12.432293 | E15: =+'[1]C-9'!E46 -> 205.1121 | F15: =+'[1]C-9'!F46 -> 219.85704 | G15: =+'[1]C-9'!G46 -> 7.1887204
A16: L eche | B16: =+'[1]C-9'!B51 -> 998.65469 | C16: =+'[1]C-9'!C51 -> 1146.6922 | D16: =+'[1]C-9'!D51 -> 14.823694 | E16: =+'[1]C-9'!E51 -> 201.95303 | F16: =+'[1]C-9'!F51 -> 191.7442 | G16: =+'[1]C-9'!G51 -> -5.0550542
A17: p/ Preliminar
A18: Fuente: Direcciones Regionales de Agricultura
A19: Elaboración: MIDAGRI - DGESEP (DEIA)

Sheet c-3
A1: C.3 PERÚ: VALOR BRUTO DE LA PRODUCCIÓN AGROPECUARIA, POR REGIÓN, ENERO-JUNIO 2020-2021
A2: (Millones de soles a precios 2007)
A4: Región | B4: Agropecuaria | H4: Agrícola | N4: Pecuario
B5: Enero - Junio | E5: Junio | H5: Enero - Junio | K5: Junio | N5: Enero - Junio | Q5: Junio
B6: 2020 p/ | C6: 2021 p/ | D6: Var. % | E6: 2020 p/ | F6: 2021 p/ | G6: Var. % | H6: 2020 p/ | I6: 2021 p/ | J6: Var. % | K6: 2020 p/ | L6: 2021 p/ | M6: Var. % | N6: 2020 p/ | O6: 2021 p/ | P6: Var. % | Q6: 2020 p/ | R6: 2021 p/ | S6: Var. %
A7: Sector/Subsector | B7: 20687.928 | C7: 20670.474 | D7: -0.084367132 | E7: 3932.3019 | F7: 4278.7816 | G7: 8.8111147 | H7: 13474.549 | I7: 13421.42 | J7: -0.39429143 | K7: 2719.6967 | L7: 3039.1589 | M7: 11.746244 | N7: 7213.3788 | O7: 7249.054 | P7: 0.49456964 | Q7: 1212.6052 | R7: 1239.6227 | S7: 2.2280485
A8: Amazonas | B8: 637.89441 | C8: 612.81307 | D8: -3.9318954 | E8: 142.86184 | F8: 146.75908 | G8: 2.7279772 | H8: 548.01921 | I8: 530.80177 | J8: -3.1417576 | K8: 128.59606 | L8: 133.3263 | M8: 3.6783756 | N8: 89.8752 | O8: 82.011295 | P8: -8.7498056 | Q8: 14.26578 | R8: 13.432772 | S8: -5.8392014
A9: Ancash | B9: 491.67537 | C9: 506.19806 | D9: 2.9537139 | E9: 61.800908 | F9: 69.406024 | G9: 12.305832 | H9: 336.32266 | I9: 351.93779 | J9: 4.6429019 | K9: 36.626155 | L9: 43.77834 | M9: 19.527533 | N9: 155.35271 | O9: 154.26026 | P9: -0.70320444 | Q9: 25.174753 | R9: 25.627684 | S9: 1.7991493
A10: Apurímac | B10: 380.52947 | C10: 386.90635 | D10: 1.6757902 | E10: 127.81803 | F10: 154.12289 | G10: 20.579931 | H10: 319.64069 | I10: 327.43673 | J10: 2.4390018 | K10: 118.22556 | L10: 144.78136 | M10: 22.461974 | N10: 60.88878 | O10: 59.469613 | P10: -2.3307527 | Q10: 9.5924656 | R10: 9.3415324 | S10: -2.6159411
A11: Arequipa | B11: 1461.9908 | C11: 1469.7091 | D11: 0.52792696 | E11: 232.18898 | F11: 216.80418 | G11: -6.6259835 | H11: 834.26095 | I11: 841.32724 | J11: 0.84701115 | K11: 129.40468 | L11: 111.55995 | M11: -13.789858 | N11: 627.7299 | O11: 628.38186 | P11: 0.10386004 | Q11: 102.7843 | R11: 105.24422 | S11: 2.3932814
A12: Ayacucho | B12: 533.63799 | C12: 464.4649 | D12: -12.962551 | E12: 108.13647 | F12: 127.3844 | G12: 17.799665 | H12: 422.52787 | I12: 355.35645 | J12: -15.897512 | K12: 87.708245 | L12: 107.35064 | M12: 22.39515 | N12: 111.11013 | O12: 109.10845 | P12: -1.8015271 | Q12: 20.428228 | R12: 20.033765 | S12: -1.9309695
A13: Cajamarca | B13: 872.01626 | C13: 903.72482 | D13: 3.6362346 | E13: 228.05017 | F13: 240.24884 | G13: 5.349118 | H13: 590.12085 | I13: 617.52437 | J13: 4.6437138 | K13: 182.05103 | L13: 192.68658 | M13: 5.8420742 | N13: 281.89541 | O13: 286.20045 | P13: 1.5271742 | Q13: 45.999145 | R13: 47.562261 | S13: 3.3981428
A14: Cusco | B14: 785.30918 | C14: 815.71859 | D14: 3.8722851 | E14: 160.849 | F14: 196.03744 | G14: 21.876686 | H14: 616.94272 | I14: 633.92199 | J14: 2.7521626 | K14: 133.0822 | L14: 165.50977 | M14: 24.366574 | N14: 168.36646 | O14: 181.7966 | P14: 7.9767332 | Q14: 27.766806 | R14: 30.527667 | S14: 9.9430254
A15: Huancavelica | B15: 330.58814 | C15: 287.87823 | D15: -12.919372 | E15: 95.863527 | F15: 90.425745 | G15: -5.6724203 | H15: 281.45805 | I15: 240.10141 | J15: -14.693711 | K15: 86.425061 | L15: 81.367445 | M15: -5.852025 | N15: 49.130093 | O15: 47.776813 | P15: -2.7544822 | Q15: 9.4384657 | R15: 9.0582997 | S15: -4.0278363
A16: Huánuco | B16: 647.09817 | C16: 668.42672 | D16: 3.2960295 | E16: 113.85392 | F16: 113.87354 | G16: 0.01723289 | H16: 489.52987 | I16: 507.44897 | J16: 3.6604713 | K16: 86.970394 | L16: 87.079957 | M16: 0.12597835 | N16: 157.56829 | O16: 160.97774 | P16: 2.1637894 | Q16: 26.883522 | R16: 26.793579 | S16: -0.33456756
A17: Ica | B17: 1609.2748 | C17: 1680.2039 | D17: 4.4075165 | E17: 239.63075 | F17: 259.55091 | G17: 8.3128576 | H17: 1004.6635 | I17: 1069.3423 | J17: 6.4378524 | K17: 138.71237 | L17: 156.44125 | M17: 12.78104 | N17: 604.61129 | O17: 610.86159 | P17: 1.0337713 | Q17: 100.91838 | R17: 103.10966 | S17: 2.1713388
A18: Junin | B18: 1138.2091 | C18: 1157.623 | D18: 1.7056519 | E18: 267.93496 | F18: 263.62992 | G18: -1.6067481 | H18: 1025.8873 | I18: 1034.4216 | J18: 0.83189569 | K18: 250.20291 | L18: 244.13913 | M18: -2.4235422 | N18: 112.32184 | O18: 123.20141 | P18: 9.6860721 | Q18: 17.732051 | R18: 19.490784 | S18: 9.9183867
... A31: Ucayali | B31: 328.62785 | C31: 382.02992 | D31: 16.250011 | E31: 63.105656 | F31: 82.710137 | G31: 31.066123 | H31: 281.87945 | I31: 335.35436 | J31: 18.970841 | K31: 53.793538 | L31: 73.190068 | M31: 36.057361 | N31: 46.748402 | O31: 46.675563 | P31: -0.15581021 | Q31: 9.3121182 | R31: 9.5200691 | S31: 2.2331205
A32: p/ Preliminar
A33: Elaboración: MIDAGRI - DGESEP (DEIA)

Sheet c-4
A1: C.4 PERÚ: VALOR DE LA PRODUCCIÓN (VBP) AGROPECUARIA POR SUBSECTORES Y
A2: PRINCIPALES PRODUCTOS. ENERO-JUNIO 2020-2021
A3: (Millones de soles a precios 2007)
A5: Principales productos | C5: Enero - Junio | F5: Junio
C6: 2020 p/ | D6: 2021 p/ | E6: Var. % | F6: 2020 p/ | G6: 2021 p/ | H6: Var. %
A7: Sector Agropecuario | C7: 20687.928 | D7: 20670.474 | E7: -0.084367132 | F7: 3932.3019 | G7: 4278.7816 | H7: 8.8111147
A8: Subsector agrícola | C8: 13474.549 | D8: 13421.42 | E8: -0.39429143 | F8: 2719.6967 | G8: 3039.1589 | H8: 11.746244
B9: Arroz cáscara | C9: 1901.1403 | D9: 1765.5916 | E9: -7.1298612 | F9: 509.12713 | G9: 668.89559 | H9: 31.380857
B10: Papa | C10: 1857.6077 | D10: 1898.6022 | E10: 2.2068461 | F10: 282.09255 | G10: 300.43691 | H10: 6.5029581
B11: Café pergamino | C11: 1310.9611 | D11: 1248.987 | E11: -4.7273848 | F11: 428.91008 | G11: 434.76433 | H11: 1.3649136
B12: Espárrago | C12: 571.03145 | D12: 494.03973 | E12: -13.482921 | F12: 92.143018 | G12: 69.154745 | H12: -24.948469
B13: MaÍz amarillo duro | C13: 379.96125 | D13: 401.72658 | E13: 5.7283006 | F13: 78.928143 | G13: 116.09908 | H13: 47.094657
B14: Alfalfa | C14: 513.66217 | D14: 513.41169 | E14: -0.048763795 | F14: 65.143585 | G14: 60.366528 | H14: -7.333121
B15: Plátano | C15: 390.80909 | D15: 387.3667 | E15: -0.88083721 | F15: 63.386093 | G15: 64.403321 | H15: 1.6048113
B16: Algodón rama | C16: 40.960584 | D16: 25.33623 | E16: -38.144853 | F16: 4.2542885 | G16: 0.91176642 | H16: -78.568298
B17: Caña de azúcar | C17: 281.73413 | D17: 252.59109 | E17: -10.344164 | F17: 54.536724 | G17: 43.549956 | H17: -20.145633
B18: Yuca | C18: 215.5915 | D18: 209.709 | E18: -2.7285375 | F18: 36.834815 | G18: 38.3106 | H18: 4.0064968
B19: Cebolla | C19: 136.27573 | D19: 164.58741 | E19: 20.775288 | F19: 22.383768 | G19: 37.176546 | H19: 66.087074
B20: Maíz Amiláceo | C20: 277.80799 | D20: 268.50784 | E20: -3.3476886 | F20: 119.60894 | G20: 133.58075 | H20: 11.681246
... B50: Oca | C50: 42.630985 | D50: 42.817932 | E50: 0.43852422 | F50: 9.9790403 | G50: 10.624244 | H50: 6.4655881
H51: sigue…
A52: continúa C.4
A53: Principales productos | C53: Enero - Junio | F53: Junio
C54: 2020 p/ | D54: 2021 p/ | E54: Var. % | F54: 2020 p/ | G54: 2021 p/ | H54: Var. %
B55: Papaya | C55: 26.397785 | D55: 27.925343 | E55: 5.7866912 | F55: 4.3255012 | G55: 4.7874841 | H55: 10.680448
B56: Quinua | C56: 107.72118 | D56: 111.74893 | E56: 3.7390522 | F56: 16.625336 | G56: 29.127493 | H56: 75.199425
B57: Orégano | C57: 33.799852 | D57: 32.727993 | E57: -3.1711936 | F57: 2.6643533 | G57: 3.9798507 | H57: 49.373983
B58: Tuna | C58: 30.012457 | D58: 24.735234 | E58: -17.583443 | F58: 0.65163938 | G58: 0.23542409 | H58: -63.872029
B59: Frijol caupí grano seco | C59: 6.3725218 | D59: 8.5774116 | E59: 34.599957 | F59: 2.054522 | G59: 4.4318686 | H59: 115.71288
B60: Haba grano verde | C60: 28.934813 | D60: 31.369224 | E60: 8.4134327 | F60: 2.4995226 | G60: 2.3167088 | H60: -7.3139513
B61: Tangelo | C61: 19.668558 | D61: 20.318636 | E61: 3.3051627 | F61: 4.6412535 | G61: 4.9730264 | H61: 7.1483475
B62: Sandía | C62: 22.173368 | D62: 19.8093 | E62: -10.661747 | F62: 1.6067304 | G62: 1.9974867 | H62: 24.319963
B63: Pallar grano seco | C63: 0.9646304 | D63: 0.86937767 | E63: -9.8745315 | F63: 0 | G63: 0.047783549 | H63: 0
B64: Granadilla | C64: 35.264875 | D64: 38.828425 | E64: 10.105096 | F64: 6.1508242 | G64: 7.2562826 | H64: 17.972524
B65: Lúcuma | C65: 17.610528 | D65: 17.61762 | E65: 0.040272777 | F65: 2.0264846 | G65: 1.9955397 | H65: -1.5270258
B66: Chirimoya | C66: 23.256811 | D66: 22.336367 | E66: -3.9577429 | F66: 3.9570214 | G66: 3.6510745 | H66: -7.7317489
... B85: Otros | C85: 1144.0825 | D85: 1181.7668 | E85: 3.2938416 | F85: 134.22727 | G85: 154.75585 | H85: 15.293894
A86: Subsector pecuario | C86: 7213.3788 | D86: 7249.054 | E86: 0.49456964 | F86: 1212.6052 | G86: 1239.6227 | H86: 2.2280485
B87: Ave | C87: 3940.6246 | D87: 3916.3582 | E87: -0.61580159 | F87: 665.36678 | G87: 678.43795 | H87: 1.9645054
B88: Ovino | C88: 199.24328 | D88: 202.67036 | E88: 1.7200486 | F88: 37.684009 | G88: 38.367086 | H88: 1.8126419
...

Sheet c-5
A1: C.5 PERÚ: PRODUCCIÓN AGROPECUARIA POR SUBSECTORES Y PRINCIPALES PRODUCTOS
A2: ENERO-JUNIO 2020-2021
A3: (Miles de toneladas)
A5: Principales productos | C5: Enero - Junio | E5: Junio
C6: 2020 p/ | D6: 2021 p/ | E6: 2020 p/ | F6: 2021 p/
A7: SECTOR AGROPECUARIO
A8: Subsector agrícola
B9: Arroz cáscara | C9: 2327.7422 | D9: 2161.7774 | E9: 623.37152 | F9: 818.99084
B10: Papa | C10: 4112.6585 | D10: 4203.4186 | E10: 624.54003 | F10: 665.1536
B11: Café pergamino | C11: 273.6714 | D11: 260.7339 | E11: 89.537682 | F11: 90.759794
B12: Espárrago | C12: 187.18844 | D12: 161.94997 | E12: 30.20518 | F12: 22.66945
B13: Maíz amarillo duro | C13: 578.65432 | D13: 611.80138 | E13: 120.20202 | F13: 176.81075
B14: Alfalfa | C14: 4398.6138 | D14: 4396.4688 | E14: 557.84033 | F14: 516.93322
B15: Plátano | C15: 1153.7596 | D15: 1143.5969 | E15: 187.13054 | F15: 190.13363
B16: Algodón rama | C16: 16.038919 | D16: 9.920897 | E16: 1.66585 | F16: 0.35702
B17: Caña de azúcar | C17: 4791.3968 | D17: 4295.7668 | E17: 927.4953 | F17: 740.64551
B18: Yuca | C18: 646.2889 | D18: 628.65467 | E18: 110.42148 | F18: 114.84551
B19: Cebolla | C19: 249.06145 | D19: 300.80468 | E19: 40.909219 | F19: 67.944925
B20: Maíz Amiláceo | C20: 229.85173 | D20: 222.15701 | E20: 98.961594 | F20: 110.52154
... B50: Oca | C50: 90.63057 | D50: 91.028007 | E50: 21.21476 | F50: 22.586419
F51: sigue…
A52: continúa C.5
A53: Principales productos | C53: Enero - Junio | E53: Junio
C54: 2020 p/ | D54: 2021 p/ | E54: 2020 p/ | F54: 2021 p/
B55: Papaya | C55: 92.540863 | D55: 97.895917 | E55: 15.163606 | F55: 16.783147
B56: Quinua | C56: 88.137337 | D56: 91.432838 | E56: 13.60283 | F56: 23.83208
B57: Orégano | C57: 6.707569 | D57: 6.494859 | E57: 0.52874 | F57: 0.7898
B58: Tuna | C58: 59.218055 | D58: 48.805482 | E58: 1.28576 | F58: 0.464519
B59: Frijol caupí grano seco | C59: 4.412517 | D59: 5.939246 | E59: 1.42261 | F59: 3.068753
B60: Haba grano verde | C60: 57.790847 | D60: 62.653041 | E60: 4.99224 | F60: 4.62711
B61: Tangelo | C61: 37.324698 | D61: 38.55834 | E61: 8.80763 | F61: 9.43723
B62: Sandía | C62: 59.003199 | D62: 52.712427 | E62: 4.2755 | F62: 5.3153
B63: Pallar grano seco | C63: 0.30685 | D63: 0.27655 | E63: 0 | F63: 0.0152
B64: Granadilla | C64: 26.225519 | D64: 28.875633 | E64: 4.574199 | F64: 5.396298
B65: Lúcuma | C65: 10.50089 | D65: 10.505119 | E65: 1.208362 | F65: 1.18991
B66: Chirimoya | C66: 17.755777 | D66: 17.053049 | E66: 3.02105 | F66: 2.78747
... B84: Té | C84: 1.096084 | D84: 1.132555 | E84: 0.11436 | F84: 0.11578
A86: Subsector pecuario
B87: Ave 2/ | C87: 1047.4502 | D87: 1040.9999 | E87: 176.85992 | F87: 180.33434
B88: Ovino 2/ | C88: 40.864174 | D88: 41.567057 | E88: 7.7288726 | F88: 7.8689694
...

Sheet c-6
A1: C.6 PERÚ: VALOR DE LA PRODUCCIÓN (VBP) AGROPECUARIA POR SUBSECTORES Y PRINCIPALES PRODUCTOS, ENERO-JUNIO 2000-2021
A2: (Millones de soles a precios 2007)
A4: Principales productos | C4: 2000 | D4: 2001 | E4: 2002 | F4: 2003 | G4: 2004 | H4: 2005 | I4: 2006 | J4: 2007 | K4: 2008 | L4: 2009 | M4: 2010 | N4: 2011 | O4: 2012 | P4: 2013 | Q4: 2014 | R4: 2015 | S4: 2016 | T4: 2017p/ | U4: 2018p/ | V4: 2019p/ | W4: 2020p/ | X4: 2021p/
A5: Sector Agropecuario | C5: 9990.927 | D5: 10051.074 | E5: 10728.814 | F5: 10999.862 | G5: 10870.32 | H5: 11587.362 | I5: 12214.319 | J5: 12763.535 | K5: 13717.649 | L5: 14106.842 | M5: 14577.563 | N5: 15242.468 | O5: 16265.311 | P5: 16650.433 | Q5: 16819.464 | R5: 17388.171 | S5: 17663.906 | T5: 17755.144 | U5: 19439.326 | V5: 20094.083 | W5: 20687.928 | X5: 20670.474
A6: Subsector agrícola | C6: 7058.6449 | D6: 7039.6042 | E6: 7582.9945 | F6: 7717.2476 | G6: 7524.8702 | H6: 8043.6865 | I6: 8410.6032 | J6: 8631.0603 | K6: 9364.1046 | L6: 9478.5161 | M6: 9756.4119 | N6: 9986.7739 | O6: 10758.358 | P6: 10968.16 | Q6: 10944.873 | R6: 11215.813 | S6: 11299.154 | T6: 11232.274 | U6: 12540.355 | V6: 12878.743 | W6: 13474.549 | X6: 13421.42
B7: Arroz cáscara | C7: 1056.8406 | D7: 1204.2842 | E7: 1255.392 | F7: 1224.5046 | G7: 980.28516 | H7: 1194.2206 | I7: 1175.3587 | J7: 1369.0478 | K7: 1467.2926 | L7: 1665.3162 | M7: 1580.9389 | N7: 1224.8016 | O7: 1603.3948 | P7: 1709.7228 | Q7: 1480.7461 | R7: 1624.5062 | S7: 1689.736 | T7: 1389.2185 | U7: 1759.7129 | V7: 1629.7094 | W7: 1901.1403 | X7: 1765.5916
B8: Papa | C8: 1149.1984 | D8: 864.16107 | E8: 1102.9048 | F8: 1095.9978 | G8: 984.37979 | H8: 1122.2435 | I8: 1052.9948 | J8: 1075.4471 | K8: 1149.4186 | L8: 1191.7729 | M8: 1197.3138 | N8: 1285.5035 | O8: 1438.6428 | P8: 1477.761 | Q8: 1511.789 | R8: 1554.9918 | S8: 1477.3123 | T8: 1533.4129 | U8: 1692.3855 | V8: 1760.5228 | W8: 1857.6077 | X8: 1898.6022
B9: Café pergamino | C9: 662.32805 | D9: 702.91025 | E9: 709.48428 | F9: 674.05034 | G9: 840.26249 | H9: 703.97002 | I9: 960.72646 | J9: 786.86228 | K9: 1016.5967 | L9: 931.91896 | M9: 990.57724 | N9: 1189.2816 | O9: 1144.625 | P9: 941.55911 | Q9: 812.00066 | R9: 949.66968 | S9: 997.66952 | T9: 1177.9472 | U9: 1298.5808 | V9: 1231.3397 | W9: 1310.9611 | X9: 1248.987
B10: Espárrago | C10: 199.12074 | D10: 248.47262 | E10: 244.33428 | F10: 261.76014 | G10: 270.73651 | H10: 270.99038 | I10: 325.63118 | J10: 356.0996 | K10: 435.59877 | L10: 386.44637 | M10: 416.62577 | N10: 529.72883 | O10: 485.88937 | P10: 486.59774 | Q10: 517.8774 | R10: 529.31743 | S10: 548.84993 | T10: 558.00396 | U10: 523.5985 | V10: 540.67456 | W10: 571.03145 | X10: 494.03973
B11: Maíz amarillo duro | C11: 285.9862 | D11: 324.96284 | E11: 301.97606 | F11: 371.67431 | G11: 344.87973 | H11: 333.05421 | I11: 305.4683 | J11: 327.26096 | K11: 375.16373 | L11: 427.95019 | M11: 403.9236 | N11: 382.82092 | O11: 436.21039 | P11: 410.45688 | Q11: 404.99002 | R11: 440.98156 | S11: 392.88381 | T11: 377.05064 | U11: 396.74319 | V11: 379.0026 | W11: 379.96125 | X11: 401.72658
B12: Alfalfa | C12: 333.83882 | D12: 336.20788 | E12: 332.89429 | F12: 349.03611 | G12: 347.2727 | H12: 357.4252 | I12: 343.09385 | J12: 359.69015 | K12: 362.53452 | L12: 382.84561 | M12: 398.30442 | N12: 414.20579 | O12: 429.54209 | P12: 459.74515 | Q12: 445.75499 | R12: 462.75372 | S12: 454.27754 | T12: 460.95761 | U12: 467.19384 | V12: 490.07349 | W12: 513.66217 | X12: 513.41169
B13: Plátano | C13: 252.98071 | D13: 267.92424 | E13: 264.14786 | F13: 276.55529 | G13: 284.58845 | H13: 289.58343 | I13: 302.61295 | J13: 318.55213 | K13: 305.34982 | L13: 316.99681 | M13: 336.31532 | N13: 334.41345 | O13: 352.76667 | P13: 357.75805 | Q13: 361.96383 | R13: 351.50717 | S13: 348.73385 | T13: 332.32611 | U13: 368.36715 | V13: 386.15349 | W13: 390.80909 | X13: 387.3667
B14: Algodón rama | C14: 261.31392 | D14: 271.34899 | E14: 304.97463 | F14: 281.76289 | G14: 369.17793 | H14: 443.3958 | I14: 398.60508 | J14: 447.21026 | K14: 356.55309 | L14: 202.43283 | M14: 132.96967 | N14: 224.32192 | O14: 240.86672 | P14: 176.54132 | Q14: 190.44691 | R14: 157.8982 | S14: 109.58655 | T14: 51.76589 | U14: 82.810249 | V14: 113.35634 | W14: 40.960584 | X14: 25.33623
B15: Caña de azúcar | C15: 187.21987 | D15: 179.98575 | E15: 219.40719 | F15: 247.21694 | G15: 201.49672 | H15: 155.74037 | I15: 175.73483 | J15: 202.07176 | K15: 238.88483 | L15: 266.80823 | M15: 262.00674 | N15: 261.61684 | O15: 259.5822 | P15: 303.97429 | Q15: 320.27789 | R15: 268.09897 | S15: 242.6578 | T15: 213.65746 | U15: 242.34986 | V15: 280.93303 | W15: 281.73413 | X15: 252.59109
B16: Yuca | C16: 144.78644 | D16: 151.03408 | E16: 144.34247 | F16: 147.44499 | G16: 154.11108 | H16: 161.49188 | I16: 169.56695 | J16: 174.03291 | K16: 168.26493 | L16: 179.68427 | M16: 188.6295 | N16: 178.33668 | O16: 183.86133 | P16: 187.05343 | Q16: 184.93162 | R16: 200.92223 | S16: 197.69425 | T16: 189.16784 | U16: 201.33455 | V16: 207.75569 | W16: 215.5915 | X16: 209.709
B17: Cebolla | C17: 104.10126 | D17: 108.32135 | E17: 113.86372 | F17: 123.51765 | G17: 118.16066 | H17: 124.90407 | I17: 132.891 | J17: 145.70992 | K17: 132.24734 | L17: 143.99162 | M17: 156.59093 | N17: 147.55423 | O17: 163.89151 | P17: 154.66736 | Q17: 138.26689 | R17: 141.65714 | S17: 150.17052 | T17: 143.46407 | U17: 132.55738 | V17: 134.23805 | W17: 136.27573 | X17: 164.58741
B18: Maíz Amiláceo | C18: 243.07326 | D18: 206.11149 | E18: 228.16294 | F18: 233.81012 | G18: 208.15127 | H18: 238.29217 | I18: 236.26713 | J18: 224.40727 | K18: 225.40941 | L18: 252.54013 | M18: 233.42978 | N18: 223.46692 | O18: 245.74397 | P18: 273.01187 | Q18: 268.54979 | R18: 262.24624 | S18: 249.34671 | T18: 226.43813 | U18: 250.36551 | V18: 253.03355 | W18: 277.80799 | X18: 268.50784
... B47: Ají | C47: 29.24063 | D47: 32.346243 | E47: 23.671844 | F47: 27.850325 | G47: 23.030759 | H47: 25.334219 | I47: 20.67395 | J47: 28.703093 | K47: 34.314956 | L47: 42.444672 | M47: 30.152902 | N47: 24.678488 | O47: 38.050303 | P47: 37.561415 | Q47: 35.211051 | R47: 29.505532 | S47: 31.900279 | T47: 35.01962 | U47: 42.638406 | V47: 35.116022 | W47: 32.793155 | X47: 38.910929
X48: sigue…
B49: continúa C.6
A50: Principales productos | C50: 2000 | D50: 2001 | E50: 2002 | F50: 2003 | G50: 2004 | H50: 2005 | I50: 2006 | J50: 2007 | K50: 2008 | L50: 2009 | M50: 2010 | N50: 2011 | O50: 2012 | P50: 2013 | Q50: 2014 | R50: 2015 | S50: 2016 | T50: 2017p/ | U50: 2018p/ | V50: 2019p/ | W50: 2020p/ | X50: 2021p/
B51: Oca | C51: 50.186695 | D51: 47.86254 | E51: 51.069839 | F51: 46.726445 | G51: 42.33454 | H51: 45.50751 | I51: 43.759209 | J51: 41.547667 | K51: 39.860068 | L51: 43.466887 | M51: 41.243883 | N51: 38.846682 | O51: 40.299867 | P51: 41.262839 | Q51: 39.237591 | R51: 40.782391 | S51: 40.416868 | T51: 41.316114 | U51: 41.708288 | V51: 39.183983 | W51: 42.630985 | X51: 42.817932
B52: Papaya | C52: 25.91965 | D52: 25.305543 | E52: 25.410442 | F52: 28.577199 | G52: 29.321492 | H52: 26.710351 | I52: 24.511754 | J52: 23.910682 | K52: 24.142589 | L52: 25.907558 | M52: 28.07519 | N52: 18.516939 | O52: 17.071569 | P52: 21.939599 | Q52: 21.636981 | R52: 20.365007 | S52: 25.241861 | T52: 26.576594 | U52: 26.203494 | V52: 23.299051 | W52: 26.397785 | X52: 27.925343
B53: Quinua | C53: 31.714606 | D53: 24.162976 | E53: 35.153787 | F53: 35.05896 | G53: 31.543889 | H53: 38.928886 | I53: 36.267111 | J53: 37.64086 | K53: 35.323261 | L53: 46.463916 | M53: 48.917648 | N53: 48.042853 | O53: 50.604057 | P53: 52.524127 | Q53: 88.541515 | R53: 105.88175 | S53: 85.525202 | T53: 86.390947 | U53: 91.697502 | V53: 89.469067 | W53: 107.72118 | X53: 111.74893
B54: Orégano | C54: 9.7616092 | D54: 14.014784 | E54: 14.299848 | F54: 12.391757 | G54: 12.804456 | H54: 13.753518 | I54: 14.763039 | J54: 16.483747 | K54: 25.100409 | L54: 27.188628 | M54: 27.362965 | N54: 30.724754 | O54: 28.503299 | P54: 33.499544 | Q54: 45.338965 | R54: 41.46122 | S54: 39.170468 | T54: 43.361481 | U54: 41.765076 | V54: 40.697707 | W54: 33.799852 | X54: 32.727993
B55: Tuna | C55: 37.219539 | D55: 32.389517 | E55: 29.99627 | F55: 29.873297 | G55: 29.174241 | H55: 30.429862 | I55: 31.815865 | J55: 31.717282 | K55: 32.62133 | L55: 37.04737 | M55: 38.603204 | N55: 37.386087 | O55: 36.772191 | P55: 37.213761 | Q55: 36.797484 | R55: 39.974431 | S55: 38.664779 | T55: 39.944527 | U55: 37.12738 | V55: 38.14618 | W55: 30.012457 | X55: 24.735234
B56: Frijol caupí grano seco | C56: 10.496388 | D56: 10.761931 | E56: 11.070681 | F56: 9.5482899 | G56: 9.7518632 | H56: 7.7159569 | I56: 19.843516 | J56: 10.141882 | K56: 17.239532 | L56: 20.007554 | M56: 29.954622 | N56: 9.815334 | O56: 31.583613 | P56: 10.123958 | Q56: 9.4087232 | R56: 8.2974463 | S56: 19.999545 | T56: 15.24749 | U56: 3.8097641 | V56: 8.9982376 | W56: 6.3725218 | X56: 8.5774116
B57: Haba grano verde | C57: 28.80994 | D57: 28.271395 | E57: 28.681351 | F57: 27.204878 | G57: 24.7719 | H57: 22.872923 | I57: 23.578228 | J57: 24.356669 | K57: 25.058791 | L57: 26.037271 | M57: 24.838009 | N57: 25.562302 | O57: 26.422721 | P57: 27.354163 | Q57: 26.634039 | R57: 28.117961 | S57: 26.221789 | T57: 29.494113 | U57: 30.069992 | V57: 28.653663 | W57: 28.934813 | X57: 31.369224
B58: Tangelo | C58: 7.8050951 | D58: 10.569202 | E58: 11.142269 | F58: 13.198149 | G58: 19.859276 | H58: 17.264892 | I58: 18.186384 | J58: 15.215145 | K58: 19.009808 | L58: 20.600606 | M58: 24.037511 | N58: 21.317031 | O58: 20.695574 | P58: 21.670426 | Q58: 22.366189 | R58: 23.511112 | S58: 21.16953 | T58: 22.782555 | U58: 21.323539 | V58: 19.84297 | W58: 19.668558 | X58: 20.318636
B59: Sandía | C59: 9.5613521 | D59: 10.418407 | E59: 10.938555 | F59: 10.541798 | G59: 13.113795 | H59: 11.508143 | I59: 12.896959 | J59: 19.050118 | K59: 20.298032 | L59: 21.057097 | M59: 18.853344 | N59: 16.473537 | O59: 18.166286 | P59: 19.829924 | Q59: 19.002906 | R59: 17.100333 | S59: 15.725706 | T59: 15.990671 | U59: 20.337637 | V59: 21.610744 | W59: 22.173368 | X59: 19.8093
B60: Pallar grano seco | C60: 3.2001775 | D60: 2.3688695 | E60: 1.2222215 | F60: 0.82332313 | G60: 0.58101024 | H60: 0.49386813 | I60: 1.0398581 | J60: 0.89562718 | K60: 1.0608577 | L60: 3.0628626 | M60: 1.7716065 | N60: 1.3663863 | O60: 1.4202088 | P60: 1.8135429 | Q60: 1.0185724 | R60: 1.484113 | S60: 1.8242627 | T60: 3.4930058 | U60: 0.93677762 | V60: 1.1664845 | W60: 0.9646304 | X60: 0.86937767
B61: Granadilla | C61: 10.544464 | D61: 9.2735011 | E61: 9.5000524 | F61: 10.062032 | G61: 11.433338 | H61: 11.08797 | I61: 12.344986 | J61: 12.396619 | K61: 14.783196 | L61: 15.694099 | M61: 16.726279 | N61: 18.460928 | O61: 21.599371 | P61: 28.541368 | Q61: 38.100094 | R61: 32.748703 | S61: 34.748881 | T61: 38.952923 | U61: 37.496266 | V61: 34.978775 | W61: 35.264875 | X61: 38.828425
B62: Lúcuma | C62: 5.1339561 | D62: 6.2651772 | E62: 8.8747859 | F62: 9.9075977 | G62: 13.11162 | H62: 13.298679 | I62: 13.855426 | J62: 16.217267 | K62: 15.452378 | L62: 18.136867 | M62: 18.232173 | N62: 19.189833 | O62: 21.019967 | P62: 22.633771 | Q62: 24.203867 | R62: 22.799551 | S62: 23.477028 | T62: 21.897558 | U62: 20.1257 | V62: 19.687045 | W62: 17.610528 | X62: 17.61762
... B82: Otros | C82: 461.54418 | D82: 455.59971 | E82: 516.96911 | F82: 514.16822 | G82: 509.22995 | H82: 535.65215 | I82: 573.33274 | J82: 639.70798 | K82: 635.48889 | L82: 744.05972 | M82: 802.33297 | N82: 840.14397 | O82: 848.08528 | P82: 904.48791 | Q82: 912.20628 | R82: 976.52923 | S82: 970.71903 | T82: 995.63777 | U82: 1066.7252 | V82: 1146.3682 | W82: 1144.0825 | X82: 1181.7668
A83: Subsector pecuario | C83: 2932.2821 | D83: 3011.4699 | E83: 3145.8195 | F83: 3282.6147 | G83: 3345.4494 | H83: 3543.6756 | I83: 3803.7162 | J83: 4132.4742 | K83: 4353.5439 | L83: 4628.3258 | M83: 4821.1515 | N83: 5255.6942 | O83: 5506.9527 | P83: 5682.2723 | Q83: 5874.591 | R83: 6172.3579 | S83: 6364.752 | T83: 6522.8703 | U83: 6898.9704 | V83: 7215.3394 | W83: 7213.3788 | X83: 7249.054
B84: Ave | C84: 1121.2883 | D84: 1135.9038 | E84: 1223.2367 | F84: 1313.029 | G84: 1301.3549 | H84: 1417.7914 | I84: 1516.2156 | J84: 1731.9265 | K84: 1905.5168 | L84: 2121.4645 | M84: 2229.5434 | N84: 2529.4233 | O84: 2701.8477 | P84: 2794.8896 | Q84: 2946.2561 | R84: 3181.7866 | S84: 3324.4506 | T84: 3414.7684 | U84: 3723.0893 | V84: 3902.6822 | W84: 3940.6246 | X84: 3916.3582
B85: Ovino | C85: 199.96905 | D85: 200.87701 | E85: 199.58678 | F85: 201.13599 | G85: 211.60679 | H85: 211.35729 | I85: 212.92962 | J85: 212.51124 | K85: 207.53954 | L85: 206.60296 | M85: 211.71676 | N85: 213.24934 | O85: 219.74658 | P85: 217.39561 | Q85: 211.37845 | R85: 202.10296 | S85: 209.14283 | T85: 205.6528 | U85: 208.19892 | V85: 208.5294 | W85: 199.24328 | X85: 202.67036
B86: Porcino | C86: 214.02673 | D86: 216.84206 | E86: 216.40811 | F86: 218.98322 | G86: 228.05929 | H86: 237.48307 | I86: 248.41069 | J86: 258.5176 | K86: 259.18048 | L86: 257.2949 | M86: 263.60702 | N86: 272.61969 | O86: 281.81039 | P86: 294.74043 | Q86: 310.72831 | R86: 331.78419 | S86: 340.57077 | T86: 365.10488 | U86: 377.80463 | V86: 395.39141 | W86: 391.19931 | X86: 401.25597
B87: Vacuno | C87: 556.45999 | D87: 552.35432 | E87: 577.57348 | F87: 592.49514 | G87: 598.97266 | H87: 638.66884 | I87: 688.37878 | J87: 694.44313 | K87: 699.28523 | L87: 703.97772 | M87: 735.03755 | N87: 764.25898 | O87: 807.37279 | P87: 822.67432 | Q87: 827.92326 | R87: 829.32507 | S87: 817.44547 | T87: 810.05528 | U87: 809.52065 | V87: 825.98686 | W87: 787.33493 | X87: 800.18272
B88: Caprino | C88: 28.756563 | D88: 28.361507 | E88: 26.71715 | F88: 28.950103 | G88: 29.19212 | H88: 29.845919 | I88: 29.82598 | J88: 30.998297 | K88: 28.924102 | L88: 27.790421 | M88: 27.859974 | N88: 28.65092 | O88: 29.408342 | P88: 30.4026 | Q88: 29.017833 | R88: 27.514783 | S88: 27.104591 | T88: 24.540736 | U88: 22.180482 | V88: 23.443682 | W88: 22.765776 | X88: 22.832705
...

Sheet c-7
A1: C.7 PERÚ: PRODUCCIÓN AGROPECUARIA POR SUBSECTORES Y PRINCIPALES PRODUCTOS, ENERO-JUNIO 2000-2021
A2: (Miles de toneladas)
A4: Principales productos | D4: 2000 | E4: 2001 | F4: 2002 | G4: 2003 | H4: 2004 | I4: 2005 | J4: 2006 | K4: 2007 | L4: 2008 | M4: 2009 | N4: 2010 | O4: 2011 | P4: 2012 | Q4: 2013 | R4: 2014 | S4: 2015 | T4: 2016 | U4: 2017p/ | V4: 2018p/ | W4: 2019p/ | X4: 2020p/ | Y4: 2021p/
A5: Sector Agropecuario
B6: Subsector agrícola
C7: Arroz cáscara | D7: 1293.9879 | E7: 1474.5167 | F7: 1537.0927 | G7: 1499.2745 | H7: 1200.2539 | I7: 1462.1949 | J7: 1439.1005 | K7: 1676.2521 | L7: 1796.5423 | M7: 2039.0009 | N7: 1935.69 | O7: 1499.6381 | P7: 1963.1848 | Q7: 2093.372 | R7: 1813.0146 | S7: 1989.0334 | T7: 2068.9004 | U7: 1700.9489 | V7: 2154.5795 | W7: 1995.4043 | X7: 2327.7422 | Y7: 2161.7774
C8: Papa | D8: 2544.2728 | E8: 1913.2131 | F8: 2441.7808 | G8: 2426.4891 | H8: 2179.3719 | I8: 2484.5958 | J8: 2331.2824 | K8: 2380.9908 | L8: 2544.7604 | M8: 2638.5307 | N8: 2650.7981 | O8: 2846.046 | P8: 3185.0895 | Q8: 3271.6954 | R8: 3347.0317 | S8: 3442.6809 | T8: 3270.7019 | U8: 3394.906 | V8: 3746.8641 | W8: 3897.7171 | X8: 4112.6585 | Y8: 4203.4186
C9: Café pergamino | D9: 138.26515 | E9: 146.73695 | F9: 148.10932 | G9: 140.71226 | H9: 175.41009 | I9: 146.95818 | J9: 200.5577 | K9: 164.26246 | L9: 212.22097 | M9: 194.54396 | N9: 206.78924 | O9: 248.27004 | P9: 238.94768 | Q9: 196.5564 | R9: 169.51026 | S9: 198.24953 | T9: 208.2698 | U9: 245.9039 | V9: 271.08693 | W9: 257.04993 | X9: 273.6714 | Y9: 260.7339
C10: Espárrago | D10: 65.27329 | E10: 81.45121 | F10: 80.09463 | G10: 85.80696 | H10: 88.74948 | I10: 88.8327 | J10: 106.74437 | K10: 116.73215 | L10: 142.79258 | M10: 126.68005 | N10: 136.57309 | O10: 173.64913 | P10: 159.27822 | Q10: 159.51043 | R10: 169.76414 | S10: 173.51427 | T10: 179.91717 | U10: 182.91793 | V10: 171.63956 | W10: 177.23722 | X10: 187.18844 | Y10: 161.94997
C11: Maíz amarillo duro | D11: 435.53691 | E11: 494.89559 | F11: 459.88835 | G11: 566.03389 | H11: 525.22763 | I11: 507.21819 | J11: 465.20678 | K11: 498.39548 | L11: 571.34803 | M11: 651.73809 | N11: 615.14729 | O11: 583.0094 | P11: 664.3178 | Q11: 625.09702 | R11: 616.77137 | S11: 671.58396 | T11: 598.33447 | U11: 574.22166 | V11: 604.21203 | W11: 577.19435 | X11: 578.65432 | Y11: 611.80138
C12: Alfalfa | D12: 2858.7428 | E12: 2879.0297 | F12: 2850.6546 | G12: 2988.8809 | H12: 2973.7804 | I12: 3060.7187 | J12: 2937.9958 | K12: 3080.114 | L12: 3104.4711 | M12: 3278.3998 | N12: 3410.7774 | O12: 3546.9447 | P12: 3678.2731 | Q12: 3936.9093 | R12: 3817.1081 | S12: 3962.6724 | T12: 3890.0888 | U12: 3947.2919 | V12: 4000.6942 | W12: 4196.6182 | X12: 4398.6138 | Y12: 4396.4688
C13: Plátano | D13: 746.85806 | E13: 790.97486 | F13: 779.8261 | G13: 816.45572 | H13: 840.1715 | I13: 854.91785 | J13: 893.38402 | K13: 940.44021 | L13: 901.46391 | M13: 935.84852 | N13: 992.8813 | O13: 987.26651 | P13: 1041.4495 | Q13: 1056.1852 | R13: 1068.6017 | S13: 1037.7312 | T13: 1029.5437 | U13: 981.10421 | V13: 1087.5058 | W13: 1140.0152 | X13: 1153.7596 | Y13: 1143.5969
C14: Algodón rama | D14: 102.32258 | E14: 106.25201 | F14: 119.41879 | G14: 110.32978 | H14: 144.55885 | I14: 173.62031 | J14: 156.08163 | K14: 175.11394 | L14: 139.61534 | M14: 79.26654 | N14: 52.066877 | O14: 87.837642 | P14: 94.316083 | Q14: 69.128213 | R14: 74.573218 | S14: 61.828132 | T14: 42.910759 | U14: 20.269948 | V14: 32.425975 | W14: 44.386897 | X14: 16.038919 | Y14: 9.920897
C15: Caña de azúcar | D15: 3184.0115 | E15: 3060.9821 | F15: 3731.4148 | G15: 4204.3698 | H15: 3426.815 | I15: 2648.6458 | J15: 2988.6876 | K15: 3436.5945 | L15: 4062.6671 | M15: 4537.555 | N15: 4455.8969 | O15: 4449.266 | P15: 4414.6633 | Q15: 5169.6307 | R15: 5446.9029 | S15: 4559.5063 | T15: 4126.8333 | U15: 3633.6303 | V15: 4121.5963 | W15: 4777.7726 | X15: 4791.3968 | Y15: 4295.7668
C16: Yuca | D16: 434.0332 | E16: 452.76204 | F16: 432.7023 | G16: 442.00288 | H16: 461.98612 | I16: 484.11191 | J16: 508.31892 | K16: 521.70673 | L16: 504.41578 | M16: 538.64808 | N16: 565.46364 | O16: 534.60835 | P16: 551.16986 | Q16: 560.73897 | R16: 554.37832 | S16: 602.31412 | T16: 592.63747 | U16: 567.07743 | V16: 603.55018 | W16: 622.79911 | X16: 646.2889 | Y16: 628.65467
C17: Cebolla | D17: 190.25847 | E17: 197.97122 | F17: 208.10061 | G17: 225.74441 | H17: 215.95383 | I17: 228.27827 | J17: 242.87541 | K17: 266.30365 | L17: 241.69904 | M17: 263.16323 | N17: 286.19008 | O17: 269.67436 | P17: 299.53284 | Q17: 282.67451 | R17: 252.70055 | S17: 258.89666 | T17: 274.45596 | U17: 262.19907 | V17: 242.26568 | W17: 245.33732 | X17: 249.06145 | Y17: 300.80468
C18: Maíz amiláceo | D18: 201.11304 | E18: 170.53175 | F18: 188.77659 | G18: 193.44894 | H18: 172.21942 | I18: 197.15728 | J18: 195.48181 | K18: 185.66924 | L18: 186.49839 | M18: 208.9457 | N18: 193.13425 | O18: 184.89122 | P18: 203.32272 | Q18: 225.88354 | R18: 222.19171 | S18: 216.97631 | T18: 206.30354 | U18: 187.34953 | V18: 207.14647 | W18: 209.35395 | X18: 229.85173 | Y18: 222.15701
... C47: Ají | D47: 22.290057 | E47: 24.657458 | F47: 18.044986 | G47: 21.230231 | H47: 17.556288 | I47: 19.31221 | J47: 15.759699 | K47: 21.880294 | L47: 26.158203 | M47: 32.355464 | N47: 22.98548 | O47: 18.812348 | P47: 29.005648 | Q47: 28.63297 | R47: 26.841294 | S47: 22.491991 | T47: 24.317501 | U47: 26.695366 | V47: 32.503147 | W47: 26.768853 | X47: 24.998138 | Y47: 29.661701
Y48: sigue…
C49: continúa C.7
A50: Principales productos | D50: 2000 | E50: 2001 | F50: 2002 | G50: 2003 | H50: 2004 | I50: 2005 | J50: 2006 | K50: 2007 | L50: 2008 | M50: 2009 | N50: 2010 | O50: 2011 | P50: 2012 | Q50: 2013 | R50: 2014 | S50: 2015 | T50: 2016 | U50: 2017p/ | V50: 2018p/ | W50: 2019p/ | X50: 2020p/ | Y50: 2021p/
C51: Oca | D51: 106.6935 | E51: 101.7525 | F51: 108.571 | G51: 99.33724 | H51: 90.000348 | I51: 96.745867 | J51: 93.029097 | K51: 88.327511 | L51: 84.73979 | M51: 92.407642 | N51: 87.681686 | O51: 82.585401 | P51: 85.674773 | Q51: 87.721985 | R51: 83.416446 | S51: 86.700586 | T51: 85.923509 | U51: 87.835245 | V51: 88.66898 | W51: 83.302478 | X51: 90.63057 | Y51: 91.028007
C52: Papaya | D52: 90.864697 | E52: 88.711867 | F52: 89.079604 | G52: 100.18108 | H52: 102.7903 | I52: 93.636603 | J52: 85.929137 | K52: 83.822 | L52: 84.634981 | M52: 90.822307 | N52: 98.421222 | O52: 64.913532 | P52: 59.846602 | Q52: 76.912114 | R52: 75.851246 | S52: 71.392176 | T52: 88.488622 | U52: 93.1677 | V52: 91.859751 | W52: 81.677848 | X52: 92.540863 | Y52: 97.895917
C53: Quinua | D53: 25.948853 | E53: 19.770118 | F53: 28.762787 | G53: 28.685199 | H53: 25.809172 | I53: 31.851568 | J53: 29.673707 | K53: 30.797707 | L53: 28.90145 | M53: 38.016721 | N53: 40.024361 | O53: 39.308605 | P53: 41.404179 | Q53: 42.975178 | R53: 72.444562 | S53: 86.632321 | T53: 69.976618 | U53: 70.68497 | V53: 75.026787 | W53: 73.203484 | X53: 88.137337 | Y53: 91.432838
C54: Orégano | D54: 1.937188 | E54: 2.781229 | F54: 2.8378 | G54: 2.45914 | H54: 2.54104 | I54: 2.729381 | J54: 2.92972 | K54: 3.271194 | L54: 4.9811676 | M54: 5.395574 | N54: 5.430171 | O54: 6.097317 | P54: 5.65647 | Q54: 6.647973 | R54: 8.997502 | S54: 8.227965 | T54: 7.773366 | U54: 8.605071 | V54: 8.288265 | W54: 8.076446 | X54: 6.707569 | Y54: 6.494859
C55: Tuna | D55: 73.438462 | E55: 63.90827 | F55: 59.186117 | G55: 58.943477 | H55: 57.564157 | I55: 60.041644 | J55: 62.776389 | K55: 62.581872 | L55: 64.365664 | M55: 73.098754 | N55: 76.168595 | O55: 73.767082 | P55: 72.555794 | Q55: 73.427062 | R55: 72.6057 | S55: 78.874184 | T55: 76.290089 | U55: 78.81518 | V55: 73.256623 | W55: 75.266833 | X55: 59.218055 | Y55: 48.805482
C56: Frijol caupí grano seco | D56: 7.268 | E56: 7.45187 | F56: 7.665657 | G56: 6.61151 | H56: 6.75247 | I56: 5.34275 | J56: 13.74022 | K56: 7.02253 | L56: 11.937147 | M56: 13.853805 | N56: 20.74144 | O56: 6.796419 | P56: 21.8694 | Q56: 7.010119 | R56: 6.51487 | S56: 5.74539 | T56: 13.848259 | U56: 10.5578 | V56: 2.63799 | W56: 6.230638 | X56: 4.412517 | Y56: 5.939246
C57: Haba grano verde | D57: 57.541441 | E57: 56.465817 | F57: 57.284614 | G57: 54.335687 | H57: 49.476355 | I57: 45.683572 | J57: 47.092262 | K57: 48.647023 | L57: 50.049356 | M57: 52.003653 | N57: 49.608394 | O57: 51.055008 | P57: 52.773503 | Q57: 54.633851 | R57: 53.195564 | S57: 56.159368 | T57: 52.372185 | U57: 58.907925 | V57: 60.058115 | W57: 57.229312 | X57: 57.790847 | Y57: 62.653041
C58: Tangelo | D58: 14.8116 | E58: 20.057 | F58: 21.1445 | G58: 25.04591 | H58: 37.68662 | I58: 32.7633 | J58: 34.512 | K58: 28.87353 | L58: 36.074598 | M58: 39.093429 | N58: 45.615587 | O58: 40.452977 | P58: 39.273648 | Q58: 41.12361 | R58: 42.443947 | S58: 44.616649 | T58: 40.173068 | U58: 43.234079 | V58: 40.465327 | W58: 37.655677 | X58: 37.324698 | Y58: 38.55834
C59: Sandía | D59: 25.4427 | E59: 27.723319 | F59: 29.107429 | G59: 28.05166 | H59: 34.895729 | I59: 30.6231 | J59: 34.31873 | K59: 50.692249 | L59: 54.012939 | M59: 56.032807 | N59: 50.168633 | O59: 43.835982 | P59: 48.340376 | Q59: 52.767307 | R59: 50.566619 | S59: 45.503883 | T59: 41.846009 | U59: 42.55108 | V59: 54.11833 | W59: 57.506058 | X59: 59.003199 | Y59: 52.712427
C60: Pallar grano seco | D60: 1.01798 | E60: 0.75354 | F60: 0.38879 | G60: 0.2619 | H60: 0.18482 | I60: 0.1571 | J60: 0.33078 | K60: 0.2849 | L60: 0.33746 | M60: 0.9743 | N60: 0.56355 | O60: 0.434649 | P60: 0.45177 | Q60: 0.57689 | R60: 0.324009 | S60: 0.472098 | T60: 0.5803 | U60: 1.111129 | V60: 0.29799 | W60: 0.37106 | X60: 0.30685 | Y60: 0.27655
C61: Granadilla | D61: 7.841628 | E61: 6.896448 | F61: 7.064928 | G61: 7.482857 | H61: 8.502659 | I61: 8.245819 | J61: 9.180627 | K61: 9.219025 | L61: 10.993857 | M61: 11.67127 | N61: 12.438874 | O61: 13.728885 | P61: 16.062859 | Q61: 21.225431 | R61: 28.333993 | S61: 24.354311 | T61: 25.841788 | U61: 28.968219 | V61: 27.884943 | W61: 26.012754 | X61: 26.225519 | Y61: 28.875633
C62: Lúcuma | D62: 3.0613 | E62: 3.73583 | F62: 5.2919 | G62: 5.90775 | H62: 7.81826 | I62: 7.9298 | J62: 8.26178 | K62: 9.67011 | L62: 9.214018 | M62: 10.814738 | N62: 10.871568 | O62: 11.442606 | P62: 12.533887 | Q62: 13.496174 | R62: 14.432398 | S62: 13.595026 | T62: 13.998995 | U62: 13.057181 | V62: 12.000649 | W62: 11.739086 | X62: 10.50089 | Y62: 10.505119
... C81: Té | D81: 3.9715 | E81: 3.8559 | F81: 3.845 | G81: 3.925 | H81: 0.728 | I81: 2.194 | J81: 3.614 | K81: 2.42915 | L81: 2.581 | M81: 1.876608 | N81: 2.039089 | O81: 2.119289 | P81: 2.37365 | Q81: 3.34138 | R81: 2.847609 | S81: 2.749165 | T81: 2.42257 | U81: 1.66644 | V81: 0.57839 | W81: 1.086959 | X81: 1.096084 | Y81: 1.132555
B82: Subsector pecuario
C83: Ave | D83: 298.04757 | E83: 301.93249 | F83: 325.1463 | G83: 349.0138 | H83: 345.91074 | I83: 376.86052 | J83: 403.02247 | K83: 460.36018 | L83: 506.50191 | M83: 563.90258 | N83: 592.63083 | O83: 672.34134 | P83: 718.17315 | Q83: 742.90446 | R83: 783.13889 | S83: 845.74484 | T83: 883.66609 | U83: 907.67328 | V83: 989.6275 | W83: 1037.3648 | X83: 1047.4502 | Y83: 1040.9999
C84: Ovino | D84: 41.013027 | E84: 41.199247 | F84: 40.934625 | G84: 41.252364 | H84: 43.39989 | I84: 43.34872 | J84: 43.6712 | K84: 43.585392 | L84: 42.565711 | M84: 42.373623 | N84: 43.422445 | O84: 43.736773 | P84: 45.069337 | Q84: 44.587161 | R84: 43.35306 | S84: 41.450686 | T84: 42.894541 | U84: 42.178746 | V84: 42.700948 | W84: 42.768729 | X84: 40.864174 | Y84: 41.567057
C85: Porcino | D85: 60.221515 | E85: 61.013676 | F85: 60.891573 | G85: 61.616141 | H85: 64.16991 | I85: 66.821513 | J85: 69.896261 | K85: 72.74008 | L85: 72.926597 | M85: 72.396045 | N85: 74.172109 | O85: 76.708037 | P85: 79.29406 | Q85: 82.932234 | R85: 87.430805 | S85: 93.35538 | T85: 95.827691 | U85: 102.73095 | V85: 106.30433 | W85: 111.25278 | X85: 110.07324 | Y85: 112.90292
C86: Vacuno | D86: 127.55579 | E86: 126.61466 | F86: 132.39558 | G86: 135.81603 | H86: 137.30085 | I86: 146.4003 | J86: 157.79517 | K86: 159.18529 | L86: 160.29523 | M86: 161.37087 | N86: 168.49063 | O86: 175.18898 | P86: 185.07184 | Q86: 188.57937 | R86: 189.78257 | S86: 190.1039 | T86: 187.38077 | U86: 185.68674 | V86: 185.56419 | W86: 189.33869 | X86: 180.47862 | Y86: 183.42368
C87: Caprino | D87: 7.818865 | E87: 7.71145 | F87: 7.2643517 | G87: 7.8714883 | H87: 7.9372924 | I87: 8.1150592 | J87: 8.1096379 | K87: 8.428389 | L87: 7.8644187 | M87: 7.5561724 | N87: 7.5750839 | O87: 7.7901408 | P87: 7.9960828 | Q87: 8.26642 | R87: 7.8899038 | S87: 7.481227 | T87: 7.3696964 | U87: 6.6725881 | V87: 6.0308388 | W87: 6.374301 | X87: 6.1899794 | Y87: 6.2081773
...

Sheet c-8
A1: C.8 PERÚ: VARIACIÓN PORCENTUAL DEL VALOR DE LA PRODUCCIÓN (VBP) AGROPECUARIA, POR SUBSECTORES Y PRINCIPALES PRODUCTOS, ENERO-JUNIO 2000-2021
A3: Principales productos | C3: 01/00 | D3: 02/01 | E3: 03/02 | F3: 04/03 | G3: 05/04 | H3: 06/05 | I3: 07/06 | J3: 08/07 | K3: 09/08 | L3: 10/09 | M3: 11/10 | N3: 12/11 | O3: 13/112 | P3: 14/13 | Q3: 15/14 | R3: 16/15 | S3: 17/16p/ | T3: 18/17p/ | U3: 19/18p/ | V3: 20/19p/ | W3: 21/20p/
A4: Sector Agropecuario | C4: 0.60201615 | D4: 6.7429608 | E4: 2.5263584 | F4: -1.1776755 | G4: 6.5963332 | H4: 5.410699 | I4: 4.4964855 | J4: 7.4753123 | K4: 2.8371723 | L4: 3.3368308 | M4: 4.5611509 | N4: 6.7104792 | O4: 2.3677507 | P4: 1.0151776 | Q4: 3.3812416 | R4: 1.5857648 | S4: 0.51652283 | T4: 9.4855953 | U4: 3.3682084 | V4: 2.9553242 | W4: -0.084367132
A5: Subsector agrícola | C5: -0.2697511 | D5: 7.7190466 | E5: 1.77045 | F5: -2.4928236 | G5: 6.8946869 | H5: 4.5615491 | I5: 2.6211812 | J5: 8.4930967 | K5: 1.2218091 | L5: 2.9318488 | M5: 2.361134 | N5: 7.72606 | O5: 1.9501341 | P5: -0.21231715 | Q5: 2.4754951 | R5: 0.74307065 | S5: -0.59190447 | T5: 11.645737 | U5: 2.6983921 | V5: 4.6262736 | W5: -0.39429143
B6: Arroz cáscara | C6: 13.951355 | D6: 4.2438311 | E6: -2.4603751 | F6: -19.944348 | G6: 21.823797 | H6: -1.5794367 | I6: 16.479153 | J6: 7.1761404 | K6: 13.495846 | L6: -5.0667396 | M6: -22.526949 | N6: 30.910573 | O6: 6.6314274 | P6: -13.392624 | Q6: 9.7086267 | R6: 4.0153655 | S6: -17.784882 | T6: 26.669269 | U6: -7.3877636 | V6: 16.655168 | W6: -7.1298612
B7: Papa | C7: -24.803144 | D7: 27.627226 | E7: -0.62625154 | F7: -10.184148 | G7: 14.005132 | H7: -6.1705561 | I7: 2.1322325 | J7: 6.8782113 | K7: 3.6848404 | L7: 0.46493186 | M7: 7.3656284 | N7: 11.912788 | O7: 2.7191055 | P7: 2.302669 | Q7: 2.8577302 | R7: -4.9954952 | S7: 3.7974751 | T7: 10.367243 | U7: 4.0261111 | V7: 5.5145475 | W7: 2.2068461
B8: Café pergamino | C8: 6.1272063 | D8: 0.93525812 | E8: -4.994324 | F8: 24.658716 | G8: -16.220226 | H8: 36.472639 | I8: -18.097157 | J8: 29.196271 | K8: -8.3295339 | L8: 6.2943549 | M8: 20.059454 | N8: -3.7549272 | O8: -17.74082 | P8: -13.759991 | Q8: 16.954299 | R8: 5.0543721 | S8: 18.069877 | T8: 10.241008 | U8: -5.1780452 | V8: 6.4662414 | W8: -4.7273848
B9: Espárrago | C9: 24.784901 | D9: -1.6655124 | E9: 7.1319763 | F9: 3.4292323 | G9: 0.093769563 | H9: 20.163373 | I9: 9.3567287 | J9: 22.324981 | K9: -11.283871 | L9: 7.809468 | M9: 27.147397 | N9: -8.2758308 | O9: 0.14578892 | P9: 6.428238 | Q9: 2.2090237 | R9: 3.6901294 | S9: 1.6678564 | T9: -6.1658089 | U9: 3.2612878 | V9: 5.6146328 | W9: -13.482921
B10: Maíz amarillo duro | C10: 13.628852 | D10: -7.0736635 | E10: 23.080721 | F10: -7.2091559 | G10: -3.4288823 | H10: -8.2827097 | I10: 7.1341817 | J10: 14.637483 | K10: 14.070245 | L10: -5.6143424 | M10: -5.2244218 | N10: 13.946328 | O10: -5.9039189 | P10: -1.3318969 | Q10: 8.8870189 | R10: -10.906974 | S10: -4.0299886 | T10: 5.2227852 | U10: -4.4715545 | V10: 0.25294132 | W10: 5.7283006
B11: Alfalfa | C11: 0.70964349 | D11: -0.9855768 | E11: 4.8489301 | F11: -0.50522037 | G11: 2.9234923 | H11: -4.0096082 | I11: 4.8372483 | J11: 0.79078489 | K11: 5.6025251 | L11: 4.0378714 | M11: 3.9922657 | N11: 3.7025788 | O11: 7.0314564 | P11: -3.0430263 | Q11: 3.8134707 | R11: -1.8316837 | S11: 1.4704828 | T11: 1.3528849 | U11: 4.8972497 | V11: 4.8132944 | W11: -0.048763795
B12: Plátano | C12: 5.9069854 | D12: -1.4094964 | E12: 4.6971524 | F12: 2.9047234 | G12: 1.7551592 | H12: 4.4993996 | I12: 5.2671853 | J12: -4.1444743 | K12: 3.8143088 | L12: 6.0942312 | M12: -0.56550446 | N12: 5.4881852 | O12: 1.414922 | P12: 1.175593 | Q12: -2.8888669 | R12: -0.78898015 | S12: -4.7049461 | T12: 10.845082 | U12: 4.8284279 | V12: 1.2056345 | W12: -0.88083721
B13: Algodón rama | C13: 3.8402353 | D13: 12.392025 | E13: -7.6110377 | F13: 31.024324 | G13: 20.10355 | H13: -10.101746 | I13: 12.193818 | J13: -20.271711 | K13: -43.225052 | L13: -34.31418 | M13: 68.701576 | N13: 7.3754724 | O13: -26.705806 | P13: 7.8766755 | Q13: -17.090701 | R13: -30.596708 | S13: -52.762551 | T13: 59.970687 | U13: 36.886854 | V13: -63.865645 | W13: -38.144853
B14: Caña de azúcar | C14: -3.8639722 | D14: 21.902533 | E14: 12.674952 | F14: -18.493967 | G14: -22.708236 | H14: 12.838326 | I14: 14.986742 | J14: 18.217821 | K14: 11.689066 | L14: -1.799606 | M14: -0.14880984 | N14: -0.77771693 | O14: 17.101358 | P14: 5.363481 | Q14: -16.291766 | R14: -9.4894695 | S14: -11.951124 | T14: 13.42916 | U14: 15.920439 | V14: 0.28515771 | W14: -10.344164
B15: Yuca | C15: 4.3150703 | D15: -4.4305271 | E15: 2.149418 | F15: 4.5210654 | G15: 4.7892764 | H15: 5.0002932 | I15: 2.6337424 | J15: -3.3143059 | K15: 6.786525 | L15: 4.9783085 | M15: -5.4566357 | N15: 3.0978764 | O15: 1.7361461 | P15: -1.1343342 | Q15: 8.6467671 | R15: -1.6065788 | S15: -4.3129295 | T15: 6.4317045 | U15: 3.1892843 | V15: 3.7716483 | W15: -2.7285375
B16: Cebolla | C16: 4.0538296 | D16: 5.1165957 | E16: 8.4784967 | F16: -4.3370199 | G16: 5.7069773 | H16: 6.3944511 | I16: 9.6461977 | J16: -9.2393078 | K16: 8.8805476 | L16: 8.7500258 | M16: -5.7708949 | N16: 11.072051 | O16: -5.6282073 | P16: -10.603701 | Q16: 2.4519603 | R16: 6.0098488 | S16: -4.465888 | T16: -7.6023856 | U16: 1.2678787 | V16: 1.5179623 | W16: 20.775288
B17: Maíz Amiláceo | C17: -15.206023 | D17: 10.698797 | E17: 2.4750659 | F17: -10.974224 | G17: 14.480287 | H17: -0.84981695 | I17: -5.0196804 | J17: 0.44656938 | K17: 12.036197 | L17: -7.5672512 | M17: -4.2680337 | N17: 9.9688346 | O17: 11.096062 | P17: -1.6343931 | Q17: -2.3472541 | R17: -4.9188606 | S17: -9.1874422 | T17: 10.566853 | U17: 1.065659 | V17: 9.7909669 | W17: -3.3476886
... B48: Papaya | C48: -2.36927 | D48: 0.41452966 | E48: 12.462425 | F48: 2.6044977 | G48: -8.9052121 | H48: -8.2312533 | I48: -2.4521799 | J48: 0.96988977 | K48: 7.3106013 | L48: 8.3667936 | M48: -34.045188 | N48: -7.8056606 | O48: 28.515423 | P48: -1.379325 | Q48: -5.8787037 | R48: 23.947226 | S48: 5.2877736 | T48: -1.4038653 | U48: -11.084183 | V48: 13.29983 | W48: 5.7866912
W49: sigue…
B50: continúa C.8
A51: Principales productos | C51: 01/00 | D51: 02/01 | E51: 03/02 | F51: 04/03 | G51: 05/04 | H51: 06/05 | I51: 07/06 | J51: 08/07 | K51: 09/08 | L51: 10/09 | M51: 11/10 | N51: 12/11 | O51: 13/112 | P51: 14/13 | Q51: 15/14 | R51: 16/15 | S51: 17/16p/ | T51: 18/17p/ | U51: 19/18p/ | V51: 20/19p/ | W51: 21/20p/
B52: Quinua | C52: -23.811207 | D52: 45.486168 | E52: -0.26975133 | F52: -10.026171 | G52: 23.411817 | H52: -6.8375315 | I52: 3.7878651 | J52: -6.157137 | K52: 31.539148 | L52: 5.2809394 | M52: -1.7883009 | N52: 5.3310821 | O52: 3.7943006 | P52: 68.573035 | Q52: 19.584298 | R52: -19.225738 | S52: 1.0122696 | T52: 6.1424897 | U52: -2.4302027 | V52: 20.400468 | W52: 3.7390522
B53: Orégano | C53: 43.570423 | D53: 2.0340288 | E53: -13.343435 | F53: 3.3304326 | G53: 7.4119652 | H53: 7.3400892 | I53: 11.655517 | J53: 52.273684 | K53: 8.3194631 | L53: 0.64121074 | M53: 12.285911 | N53: -7.2301801 | O53: 17.528653 | P53: 35.342036 | Q53: -8.552785 | R53: -5.5250478 | S53: 10.699419 | T53: -3.6816198 | U53: -2.5556495 | V53: -16.949002 | W53: -3.1711936
B54: Tuna | C54: -12.977113 | D54: -7.3889545 | E54: -0.409961 | F54: -2.3400723 | G54: 4.3038709 | H54: 4.554747 | I54: -0.30985694 | J54: 2.8503334 | K54: 13.567933 | L54: 4.1995805 | M54: -3.1528913 | N54: -1.6420441 | O54: 1.2008248 | P54: -1.1186094 | Q54: 8.6335976 | R54: -3.2762241 | S54: 3.3098546 | T54: -7.0526477 | U54: 2.7440659 | V54: -21.32251 | W54: -17.583443
B55: Frijol caupí grano seco | C55: 2.5298569 | D55: 2.868904 | E55: -13.751554 | F55: 2.1320394 | G55: -20.877101 | H55: 157.17505 | I55: -48.890702 | J55: 69.983567 | K55: 16.056249 | L55: 49.716558 | M55: -67.232656 | N55: 221.77828 | O55: -67.945536 | P55: -7.0647731 | Q55: -11.811134 | R55: 141.03253 | S55: -23.760814 | T55: -75.013829 | U55: 136.18884 | V55: -29.180334 | W55: 34.599957
B56: Haba grano verde | C56: -1.8693032 | D56: 1.4500755 | E56: -5.1478517 | F56: -8.9431684 | G56: -7.6658497 | H56: 3.0835811 | I56: 3.3015212 | J56: 2.8826697 | K56: 3.9047396 | L56: -4.6059437 | M56: 2.916067 | N56: 3.3659675 | O56: 3.5251554 | P56: -2.6325931 | Q56: 5.5715247 | R56: -6.7436354 | S56: 12.479411 | T56: 1.9525217 | U56: -4.7101095 | V56: 0.98120173 | W56: 8.4134327
B57: Tangelo | C57: 35.414135 | D57: 5.4220472 | E57: 18.451181 | F57: 50.470157 | G57: -13.063841 | H57: 5.3373744 | I57: -16.337709 | J57: 24.940033 | K57: 8.3683012 | L57: 16.683515 | M57: -11.317645 | N57: -2.9153083 | O57: 4.710441 | P57: 3.2106544 | Q57: 5.1189914 | R57: -9.9594683 | S57: 7.6195599 | T57: -6.4040962 | U57: -6.9433518 | V57: -0.87896176 | W57: 3.3051627
B58: Sandía | C58: 8.963746 | D58: 4.992584 | E58: -3.6271462 | F58: 24.398089 | G58: -12.243988 | H58: 12.068112 | I58: 47.710154 | J58: 6.5506859 | K58: 3.7396002 | L58: -10.465608 | M58: -12.62273 | N58: 10.275563 | O58: 9.1578332 | P58: -4.170552 | Q58: -10.012012 | R58: -8.0385975 | S58: 1.6849181 | T58: 27.184386 | U58: 6.2598532 | V58: 2.6034492 | W58: -10.661747
B59: Pallar grano seco | C59: -25.976935 | D59: -48.404862 | E59: -32.637156 | F59: -29.431081 | G59: -14.998377 | H59: 110.55379 | I59: -13.870246 | J59: 18.448578 | K59: 188.7157 | L59: -42.158473 | M59: -22.873037 | N59: 3.9390405 | O59: 27.695509 | P59: -43.83522 | Q59: 45.705212 | R59: 22.919394 | S59: 91.474927 | T59: -73.181332 | U59: 24.520957 | V59: -17.304479 | W59: -9.8745315
B60: Granadilla | C60: -12.053364 | D60: 2.4429967 | E60: 5.9155451 | F60: 13.628511 | G60: -3.0207021 | H60: 11.336751 | I60: 0.4182503 | J60: 19.251841 | K60: 6.1617411 | L60: 6.5768678 | M60: 10.370802 | N60: 17.000463 | O60: 32.139808 | P60: 33.490778 | Q60: -14.045609 | R60: 6.1076538 | S60: 12.098354 | T60: -3.7395326 | U60: -6.7139782 | V60: 0.8179257 | W60: 10.105096
B61: Lúcuma | C61: 22.034103 | D61: 41.652591 | E61: 11.637597 | F61: 32.339046 | G61: 1.4266602 | H61: 4.1864864 | I61: 17.046327 | J61: -4.716513 | K61: 17.37266 | L61: 0.52548661 | M61: 5.2525818 | N61: 9.5369971 | O61: 7.6774827 | P61: 6.9369586 | Q61: -5.8020296 | R61: 2.9714471 | S61: -6.7277258 | T61: -8.0915781 | U61: -2.1795738 | V61: -10.547635 | W61: 0.040272777
B62: Chirimoya | C62: 5.993028 | D62: 48.906522 | E62: -8.4452607 | F62: -13.684002 | G62: 5.9780412 | H62: -6.1542993 | I62: 8.606839 | J62: 5.9948747 | K62: 20.584563 | L62: 3.9163192 | M62: -4.428138 | N62: -13.878954 | O62: 35.842611 | P62: -21.633695 | Q62: 16.800541 | R62: 29.860293 | S62: -3.3032038 | T62: -15.709511 | U62: 5.7694233 | V62: -2.0623968 | W62: -3.9577429
B63: Maracuyá | C63: -22.873075 | D63: 11.837097 | E63: 21.183078 | F63: -3.8461218 | G63: -5.5818889 | H63: 7.1905181 | I63: 35.654199 | J63: 10.967256 | K63: 24.375106 | L63: 0.67673355 | M63: 82.581802 | N63: -27.966438 | O63: -15.316615 | P63: 4.5568783 | Q63: 41.853226 | R63: -7.3385555 | S63: -7.2655214 | T63: 20.147743 | U63: -12.884632 | V63: 27.044531 | W63: 14.453013
... B81: Otros | C81: -1.2879525 | D81: 13.470028 | E81: -0.54179187 | F81: -0.9604375 | G81: 5.1886569 | H81: 7.0345271 | I81: 11.577088 | J81: -0.65953472 | K81: 17.084615 | L81: 7.8317986 | M81: 4.7126309 | N81: 0.94523303 | O81: 6.6505844 | P81: 0.85334119 | Q81: 7.0513603 | R81: -0.5949847 | S81: 2.5670392 | T81: 7.13989 | U81: 7.4661242 | V81: -0.19939101 | W81: 3.2938417
A82: Subsector pecuario | C82: 2.7005508 | D82: 4.4612653 | E82: 4.3484749 | F82: 1.914166 | G82: 5.9252507 | H82: 7.3381596 | I82: 8.6430724 | J82: 5.3495741 | K82: 6.3116817 | L82: 4.1662082 | M82: 9.0132555 | N82: 4.7806911 | O82: 3.1836047 | P82: 3.3845396 | Q82: 5.0687261 | R82: 3.1170272 | S82: 2.4842807 | T82: 5.7658671 | U82: 4.5857429 | V82: -0.027172828 | W82: 0.49456964
B83: Ave | C83: 1.3034581 | D83: 7.6884093 | E83: 7.3405432 | F83: -0.88909513 | G83: 8.9473302 | H83: 6.942079 | I83: 14.226927 | J83: 10.022962 | K83: 11.332764 | L83: 5.0945412 | M83: 13.450282 | N83: 6.8167469 | O83: 3.4436411 | P83: 5.4158289 | Q83: 7.994233 | R83: 4.4837697 | S83: 2.7167721 | T83: 9.0290436 | U83: 4.8237604 | V83: 0.97221296 | W83: -0.61580159
B84: Ovino | C84: 0.45405085 | D84: -0.64229814 | E84: 0.77620971 | F84: 5.2058263 | G84: -0.1179036 | H84: 0.74391928 | I84: -0.19648643 | J84: -2.3395009 | K84: -0.45127588 | L84: 2.4751782 | M84: 0.72388339 | N84: 3.0467807 | O84: -1.0698523 | P84: -2.7678401 | Q84: -4.3880957 | R84: 3.4833075 | S84: -1.6687315 | T84: 1.2380686 | U84: 0.15873311 | V84: -4.4531486 | W84: 1.7200486
B85: Porcino | C85: 1.3154125 | D85: -0.20012377 | E85: 1.1899306 | F85: 4.1446434 | G85: 4.1321594 | H85: 4.601434 | I85: 4.0686283 | J85: 0.25641549 | K85: -0.72751478 | L85: 2.4532616 | M85: 3.4189778 | N85: 3.3712539 | O85: 4.5882052 | P85: 5.4243936 | Q85: 6.7763018 | R85: 2.6482795 | S85: 7.2038213 | T85: 3.4783857 | U85: 4.6549931 | V85: -1.0602408 | W85: 2.5707262
B86: Vacuno | C86: -0.73781941 | D86: 4.5657584 | E86: 2.5835082 | F86: 1.0932606 | G86: 6.6273782 | H86: 7.7833667 | I86: 0.88096146 | J86: 0.69726362 | K86: 0.67104145 | L86: 4.4120464 | M86: 3.9755023 | N86: 5.6412566 | O86: 1.8952248 | P86: 0.6380331 | Q86: 0.16931699 | R86: -1.4324416 | S86: -0.90405939 | T86: -0.065999813 | U86: 2.0340692 | V86: -4.6794845 | W86: 1.631807
B87: Caprino | C87: -1.3737927 | D87: -5.7978503 | E87: 8.3577537 | F87: 0.83598009 | G87: 2.2396411 | H87: -0.066806287 | I87: 3.930522 | J87: -6.6913174 | K87: -3.9195058 | L87: 0.25027899 | M87: 2.8390042 | N87: 2.6436231 | O87: 3.3808701 | P87: -4.5547672 | Q87: -5.1797441 | R87: -1.4908053 | S87: -9.4591185 | T87: -9.6176965 | U87: 5.6950976 | V87: -2.8916369 | W87: 0.29399027
B88: Alpaca | C88: 4.8635019 | D88: 2.8911068 | E88: 0.16120877 | F88: 1.3328995 | G88: 6.1200926 | H88: 2.7842448 | I88: 3.4774841 | J88: -0.54149842 | K88: 7.4102845 | L88: 4.2008667 | M88: 6.5462403 | N88: 5.0155396 | O88: 2.9226186 | P88: 2.8867411 | Q88: -4.8641852 | R88: 5.8757078 | S88: 2.7878117 | T88: -1.1465254 | U88: -0.034894361 | V88: -1.7024823 | W88: 2.8434912
...

